
	Sun May 24 07:42:19 2020
--------------
wx._core.wxAssertionError: C++ assertion "Assert failure" failed at ..\..\src\common\unichar.cpp(65) in wxUniChar::ToHi8bit(): character cannot be converted to single byte

--------------

	Sun May 24 07:42:19 2020
--------------

The above exception was the direct cause of the following exception:


--------------

	Sun May 24 07:42:19 2020
--------------
SystemError: <class 'wx._core.CommandEvent'> returned a result with an error set

--------------

	Sun May 24 09:19:03 2020
--------------
Traceback (most recent call last):

--------------

	Sun May 24 09:19:03 2020
--------------
  File "D:\project\碧蓝航线立绘导出2.0\core\src\structs_classes\drop_order.py", line 38, in OnDropFiles

--------------

	Sun May 24 09:19:03 2020
--------------
    True, '', self.frame.names, self.data.fi_texture_type)

--------------

	Sun May 24 09:19:03 2020
--------------
  File "D:\project\碧蓝航线立绘导出2.0\core\src\static_classes\file_read.py", line 71, in file_deal

--------------

	Sun May 24 09:19:03 2020
--------------
    num += len(list(map(info_write2, path)))

--------------

	Sun May 24 09:19:03 2020
--------------
  File "D:\project\碧蓝航线立绘导出2.0\core\src\static_classes\file_read.py", line 34, in info_write

--------------

	Sun May 24 09:19:03 2020
--------------
    info_group.set_tex(per_path, key)

--------------

	Sun May 24 09:19:03 2020
--------------
  File "D:\project\碧蓝航线立绘导出2.0\core\src\structs_classes\extract_structs.py", line 348, in set_tex

--------------

	Sun May 24 09:19:03 2020
--------------
    val.tex_step = 0

--------------

	Sun May 24 09:19:03 2020
--------------
TypeError: 'NoneType' object is not subscriptable

--------------

	Sun May 24 09:20:02 2020
--------------
Traceback (most recent call last):

--------------

	Sun May 24 09:20:02 2020
--------------
  File "D:\project\碧蓝航线立绘导出2.0\core\src\structs_classes\drop_order.py", line 38, in OnDropFiles

--------------

	Sun May 24 09:20:02 2020
--------------
    True, '', self.frame.names, self.data.fi_texture_type)

--------------

	Sun May 24 09:20:02 2020
--------------
  File "D:\project\碧蓝航线立绘导出2.0\core\src\static_classes\file_read.py", line 71, in file_deal

--------------

	Sun May 24 09:20:02 2020
--------------
    num += len(list(map(info_write2, path)))

--------------

	Sun May 24 09:20:02 2020
--------------
  File "D:\project\碧蓝航线立绘导出2.0\core\src\static_classes\file_read.py", line 34, in info_write

--------------

	Sun May 24 09:20:02 2020
--------------
    info_group.set_tex(per_path, key)

--------------

	Sun May 24 09:20:02 2020
--------------
  File "D:\project\碧蓝航线立绘导出2.0\core\src\structs_classes\extract_structs.py", line 348, in set_tex

--------------

	Sun May 24 09:20:02 2020
--------------
    val.tex_step = 0

--------------

	Sun May 24 09:20:02 2020
--------------
TypeError: 'NoneType' object is not subscriptable

--------------

	Sun May 24 09:25:49 2020
--------------
Traceback (most recent call last):

--------------

	Sun May 24 09:25:49 2020
--------------
  File "D:\Program Files\JetBrains\PyCharm Community Edition 2018.3.4\plugins\python-ce\helpers\pydev\pydevd.py", line 1434, in _exec

--------------

	Sun May 24 09:25:49 2020
--------------
    pydev_imports.execfile(file, globals, locals)  # execute the script

--------------

	Sun May 24 09:25:49 2020
--------------
  File "D:\Program Files\JetBrains\PyCharm Community Edition 2018.3.4\plugins\python-ce\helpers\pydev\_pydev_imps\_pydev_execfile.py", line 18, in execfile

--------------

	Sun May 24 09:25:49 2020
--------------
    exec(compile(contents+"\n", file, 'exec'), glob, loc)

--------------

	Sun May 24 09:25:49 2020
--------------
  File "D:/project/碧蓝航线立绘导出2.0/Main.py", line 36, in <module>

--------------

	Sun May 24 09:25:49 2020
--------------
    MainFrame.run(path)

--------------

	Sun May 24 09:25:49 2020
--------------
  File "D:\project\碧蓝航线立绘导出2.0\core\src\frame_classes\main_frame.py", line 84, in run

--------------

	Sun May 24 09:25:49 2020
--------------
    frame = MainFrame(None, path)

--------------

	Sun May 24 09:25:49 2020
--------------
  File "D:\project\碧蓝航线立绘导出2.0\core\src\frame_classes\main_frame.py", line 47, in __init__

--------------

	Sun May 24 09:25:49 2020
--------------
    self.painting_work = PerWorkList(mesh_match=self.height_setting[self.data.sk_mash_match],

--------------

	Sun May 24 09:25:49 2020
--------------
AttributeError: 'MainFrame' object has no attribute 'data'

--------------

	Sun May 24 19:23:08 2020
--------------
Traceback (most recent call last):

--------------

	Sun May 24 19:23:08 2020
--------------
  File "C:\Users\qz228\AppData\Local\Programs\Python\Python37\lib\site-packages\urllib3\connection.py", line 157, in _new_conn

--------------

	Sun May 24 19:23:08 2020
--------------
    (self._dns_host, self.port), self.timeout, **extra_kw

--------------

	Sun May 24 19:23:08 2020
--------------
  File "C:\Users\qz228\AppData\Local\Programs\Python\Python37\lib\site-packages\urllib3\util\connection.py", line 61, in create_connection

--------------

	Sun May 24 19:23:08 2020
--------------
    for res in socket.getaddrinfo(host, port, family, socket.SOCK_STREAM):

--------------

	Sun May 24 19:23:08 2020
--------------
  File "C:\Users\qz228\AppData\Local\Programs\Python\Python37\lib\socket.py", line 752, in getaddrinfo

--------------

	Sun May 24 19:23:08 2020
--------------
    for res in _socket.getaddrinfo(host, port, family, type, proto, flags):

--------------

	Sun May 24 19:23:08 2020
--------------
socket.gaierror: [Errno 11004] getaddrinfo failed

--------------

	Sun May 24 19:23:08 2020
--------------

During handling of the above exception, another exception occurred:


--------------

	Sun May 24 19:23:08 2020
--------------
Traceback (most recent call last):

--------------

	Sun May 24 19:23:08 2020
--------------
  File "C:\Users\qz228\AppData\Local\Programs\Python\Python37\lib\site-packages\urllib3\connectionpool.py", line 672, in urlopen

--------------

	Sun May 24 19:23:08 2020
--------------
    chunked=chunked,

--------------

	Sun May 24 19:23:08 2020
--------------
  File "C:\Users\qz228\AppData\Local\Programs\Python\Python37\lib\site-packages\urllib3\connectionpool.py", line 376, in _make_request

--------------

	Sun May 24 19:23:08 2020
--------------
    self._validate_conn(conn)

--------------

	Sun May 24 19:23:08 2020
--------------
  File "C:\Users\qz228\AppData\Local\Programs\Python\Python37\lib\site-packages\urllib3\connectionpool.py", line 994, in _validate_conn

--------------

	Sun May 24 19:23:08 2020
--------------
    conn.connect()

--------------

	Sun May 24 19:23:08 2020
--------------
  File "C:\Users\qz228\AppData\Local\Programs\Python\Python37\lib\site-packages\urllib3\connection.py", line 300, in connect

--------------

	Sun May 24 19:23:08 2020
--------------
    conn = self._new_conn()

--------------

	Sun May 24 19:23:08 2020
--------------
  File "C:\Users\qz228\AppData\Local\Programs\Python\Python37\lib\site-packages\urllib3\connection.py", line 169, in _new_conn

--------------

	Sun May 24 19:23:08 2020
--------------
    self, "Failed to establish a new connection: %s" % e

--------------

	Sun May 24 19:23:08 2020
--------------
urllib3.exceptions.NewConnectionError: <urllib3.connection.VerifiedHTTPSConnection object at 0x00000216493D9B48>: Failed to establish a new connection: [Errno 11004] getaddrinfo failed

--------------

	Sun May 24 19:23:08 2020
--------------

During handling of the above exception, another exception occurred:


--------------

	Sun May 24 19:23:08 2020
--------------
Traceback (most recent call last):

--------------

	Sun May 24 19:23:08 2020
--------------
  File "C:\Users\qz228\AppData\Local\Programs\Python\Python37\lib\site-packages\requests\adapters.py", line 449, in send

--------------

	Sun May 24 19:23:08 2020
--------------
    timeout=timeout

--------------

	Sun May 24 19:23:08 2020
--------------
  File "C:\Users\qz228\AppData\Local\Programs\Python\Python37\lib\site-packages\urllib3\connectionpool.py", line 720, in urlopen

--------------

	Sun May 24 19:23:08 2020
--------------
    method, url, error=e, _pool=self, _stacktrace=sys.exc_info()[2]

--------------

	Sun May 24 19:23:08 2020
--------------
  File "C:\Users\qz228\AppData\Local\Programs\Python\Python37\lib\site-packages\urllib3\util\retry.py", line 436, in increment

--------------

	Sun May 24 19:23:08 2020
--------------
    raise MaxRetryError(_pool, url, error or ResponseError(cause))

--------------

	Sun May 24 19:23:08 2020
--------------
urllib3.exceptions.MaxRetryError: HTTPSConnectionPool(host='raw.githubusercontent.com', port=443): Max retries exceeded with url: /OSSSY152/AzurLanePaintingLocalization/master/chs/names.json (Caused by NewConnectionError('<urllib3.connection.VerifiedHTTPSConnection object at 0x00000216493D9B48>: Failed to establish a new connection: [Errno 11004] getaddrinfo failed'))

--------------

	Sun May 24 19:23:08 2020
--------------

During handling of the above exception, another exception occurred:


--------------

	Sun May 24 19:23:08 2020
--------------
Traceback (most recent call last):

--------------

	Sun May 24 19:23:08 2020
--------------
  File "D:\project\碧蓝航线立绘导出2.0\core\src\frame_classes\location_update.py", line 60, in request_info

--------------

	Sun May 24 19:23:08 2020
--------------
    work()

--------------

	Sun May 24 19:23:08 2020
--------------
  File "D:\project\碧蓝航线立绘导出2.0\core\src\frame_classes\location_update.py", line 51, in work

--------------

	Sun May 24 19:23:08 2020
--------------
    r = requests.get(self.available_list[index], timeout=1000)

--------------

	Sun May 24 19:23:08 2020
--------------
  File "C:\Users\qz228\AppData\Local\Programs\Python\Python37\lib\site-packages\requests\api.py", line 75, in get

--------------

	Sun May 24 19:23:08 2020
--------------
    return request('get', url, params=params, **kwargs)

--------------

	Sun May 24 19:23:08 2020
--------------
  File "C:\Users\qz228\AppData\Local\Programs\Python\Python37\lib\site-packages\requests\api.py", line 60, in request

--------------

	Sun May 24 19:23:08 2020
--------------
    return session.request(method=method, url=url, **kwargs)

--------------

	Sun May 24 19:23:08 2020
--------------
  File "C:\Users\qz228\AppData\Local\Programs\Python\Python37\lib\site-packages\requests\sessions.py", line 533, in request

--------------

	Sun May 24 19:23:08 2020
--------------
    resp = self.send(prep, **send_kwargs)

--------------

	Sun May 24 19:23:08 2020
--------------
  File "C:\Users\qz228\AppData\Local\Programs\Python\Python37\lib\site-packages\requests\sessions.py", line 646, in send

--------------

	Sun May 24 19:23:08 2020
--------------
    r = adapter.send(request, **kwargs)

--------------

	Sun May 24 19:23:08 2020
--------------
  File "C:\Users\qz228\AppData\Local\Programs\Python\Python37\lib\site-packages\requests\adapters.py", line 516, in send

--------------

	Sun May 24 19:23:08 2020
--------------
    raise ConnectionError(e, request=request)

--------------

	Sun May 24 19:23:08 2020
--------------
requests.exceptions.ConnectionError: HTTPSConnectionPool(host='raw.githubusercontent.com', port=443): Max retries exceeded with url: /OSSSY152/AzurLanePaintingLocalization/master/chs/names.json (Caused by NewConnectionError('<urllib3.connection.VerifiedHTTPSConnection object at 0x00000216493D9B48>: Failed to establish a new connection: [Errno 11004] getaddrinfo failed'))

--------------

	Sun May 24 19:23:08 2020
--------------
Error in atexit._run_exitfuncs:

--------------

	Sun May 24 19:23:08 2020
--------------
wx._core.wxAssertionError: C++ assertion "IsRunning()" failed at ..\..\src\common\evtloopcmn.cpp(83) in wxEventLoopBase::Exit(): Use ScheduleExit() on not running loop

--------------

	Mon May 25 10:23:35 2020
--------------
Traceback (most recent call last):

--------------

	Mon May 25 10:23:35 2020
--------------
  File "C:\Users\qz228\AppData\Local\Programs\Python\Python37\lib\site-packages\urllib3\connection.py", line 157, in _new_conn

--------------

	Mon May 25 10:23:35 2020
--------------
    (self._dns_host, self.port), self.timeout, **extra_kw

--------------

	Mon May 25 10:23:35 2020
--------------
  File "C:\Users\qz228\AppData\Local\Programs\Python\Python37\lib\site-packages\urllib3\util\connection.py", line 61, in create_connection

--------------

	Mon May 25 10:23:35 2020
--------------
    for res in socket.getaddrinfo(host, port, family, socket.SOCK_STREAM):

--------------

	Mon May 25 10:23:35 2020
--------------
  File "C:\Users\qz228\AppData\Local\Programs\Python\Python37\lib\socket.py", line 752, in getaddrinfo

--------------

	Mon May 25 10:23:35 2020
--------------
    for res in _socket.getaddrinfo(host, port, family, type, proto, flags):

--------------

	Mon May 25 10:23:35 2020
--------------
socket.gaierror: [Errno 11004] getaddrinfo failed

--------------

	Mon May 25 10:23:35 2020
--------------

During handling of the above exception, another exception occurred:


--------------

	Mon May 25 10:23:35 2020
--------------
Traceback (most recent call last):

--------------

	Mon May 25 10:23:35 2020
--------------
  File "C:\Users\qz228\AppData\Local\Programs\Python\Python37\lib\site-packages\urllib3\connectionpool.py", line 672, in urlopen

--------------

	Mon May 25 10:23:35 2020
--------------
    chunked=chunked,

--------------

	Mon May 25 10:23:35 2020
--------------
  File "C:\Users\qz228\AppData\Local\Programs\Python\Python37\lib\site-packages\urllib3\connectionpool.py", line 376, in _make_request

--------------

	Mon May 25 10:23:35 2020
--------------
    self._validate_conn(conn)

--------------

	Mon May 25 10:23:35 2020
--------------
  File "C:\Users\qz228\AppData\Local\Programs\Python\Python37\lib\site-packages\urllib3\connectionpool.py", line 994, in _validate_conn

--------------

	Mon May 25 10:23:35 2020
--------------
    conn.connect()

--------------

	Mon May 25 10:23:35 2020
--------------
  File "C:\Users\qz228\AppData\Local\Programs\Python\Python37\lib\site-packages\urllib3\connection.py", line 300, in connect

--------------

	Mon May 25 10:23:35 2020
--------------
    conn = self._new_conn()

--------------

	Mon May 25 10:23:35 2020
--------------
  File "C:\Users\qz228\AppData\Local\Programs\Python\Python37\lib\site-packages\urllib3\connection.py", line 169, in _new_conn

--------------

	Mon May 25 10:23:35 2020
--------------
    self, "Failed to establish a new connection: %s" % e

--------------

	Mon May 25 10:23:35 2020
--------------
urllib3.exceptions.NewConnectionError: <urllib3.connection.VerifiedHTTPSConnection object at 0x0000019A3E623E88>: Failed to establish a new connection: [Errno 11004] getaddrinfo failed

--------------

	Mon May 25 10:23:35 2020
--------------

During handling of the above exception, another exception occurred:


--------------

	Mon May 25 10:23:35 2020
--------------
Traceback (most recent call last):

--------------

	Mon May 25 10:23:35 2020
--------------
  File "C:\Users\qz228\AppData\Local\Programs\Python\Python37\lib\site-packages\requests\adapters.py", line 449, in send

--------------

	Mon May 25 10:23:35 2020
--------------
    timeout=timeout

--------------

	Mon May 25 10:23:35 2020
--------------
  File "C:\Users\qz228\AppData\Local\Programs\Python\Python37\lib\site-packages\urllib3\connectionpool.py", line 720, in urlopen

--------------

	Mon May 25 10:23:35 2020
--------------
    method, url, error=e, _pool=self, _stacktrace=sys.exc_info()[2]

--------------

	Mon May 25 10:23:35 2020
--------------
  File "C:\Users\qz228\AppData\Local\Programs\Python\Python37\lib\site-packages\urllib3\util\retry.py", line 436, in increment

--------------

	Mon May 25 10:23:35 2020
--------------
    raise MaxRetryError(_pool, url, error or ResponseError(cause))

--------------

	Mon May 25 10:23:35 2020
--------------
urllib3.exceptions.MaxRetryError: HTTPSConnectionPool(host='raw.githubusercontent.com', port=443): Max retries exceeded with url: /OSSSY152/AzurLanePaintingLocalization/master/chs/names.json (Caused by NewConnectionError('<urllib3.connection.VerifiedHTTPSConnection object at 0x0000019A3E623E88>: Failed to establish a new connection: [Errno 11004] getaddrinfo failed'))

--------------

	Mon May 25 10:23:35 2020
--------------

During handling of the above exception, another exception occurred:


--------------

	Mon May 25 10:23:35 2020
--------------
Traceback (most recent call last):

--------------

	Mon May 25 10:23:35 2020
--------------
  File "D:\project\碧蓝航线立绘导出2.0\core\src\frame_classes\location_update.py", line 60, in request_info

--------------

	Mon May 25 10:23:35 2020
--------------
    work()

--------------

	Mon May 25 10:23:35 2020
--------------
  File "D:\project\碧蓝航线立绘导出2.0\core\src\frame_classes\location_update.py", line 51, in work

--------------

	Mon May 25 10:23:35 2020
--------------
    r = requests.get(self.available_list[index], timeout=1000)

--------------

	Mon May 25 10:23:35 2020
--------------
  File "C:\Users\qz228\AppData\Local\Programs\Python\Python37\lib\site-packages\requests\api.py", line 75, in get

--------------

	Mon May 25 10:23:35 2020
--------------
    return request('get', url, params=params, **kwargs)

--------------

	Mon May 25 10:23:35 2020
--------------
  File "C:\Users\qz228\AppData\Local\Programs\Python\Python37\lib\site-packages\requests\api.py", line 60, in request

--------------

	Mon May 25 10:23:35 2020
--------------
    return session.request(method=method, url=url, **kwargs)

--------------

	Mon May 25 10:23:35 2020
--------------
  File "C:\Users\qz228\AppData\Local\Programs\Python\Python37\lib\site-packages\requests\sessions.py", line 533, in request

--------------

	Mon May 25 10:23:35 2020
--------------
    resp = self.send(prep, **send_kwargs)

--------------

	Mon May 25 10:23:35 2020
--------------
  File "C:\Users\qz228\AppData\Local\Programs\Python\Python37\lib\site-packages\requests\sessions.py", line 646, in send

--------------

	Mon May 25 10:23:35 2020
--------------
    r = adapter.send(request, **kwargs)

--------------

	Mon May 25 10:23:35 2020
--------------
  File "C:\Users\qz228\AppData\Local\Programs\Python\Python37\lib\site-packages\requests\adapters.py", line 516, in send

--------------

	Mon May 25 10:23:35 2020
--------------
    raise ConnectionError(e, request=request)

--------------

	Mon May 25 10:23:35 2020
--------------
requests.exceptions.ConnectionError: HTTPSConnectionPool(host='raw.githubusercontent.com', port=443): Max retries exceeded with url: /OSSSY152/AzurLanePaintingLocalization/master/chs/names.json (Caused by NewConnectionError('<urllib3.connection.VerifiedHTTPSConnection object at 0x0000019A3E623E88>: Failed to establish a new connection: [Errno 11004] getaddrinfo failed'))

--------------

	Mon May 25 10:23:35 2020
--------------
Error in atexit._run_exitfuncs:

--------------

	Mon May 25 10:23:35 2020
--------------
wx._core.wxAssertionError: C++ assertion "IsRunning()" failed at ..\..\src\common\evtloopcmn.cpp(83) in wxEventLoopBase::Exit(): Use ScheduleExit() on not running loop

--------------

	Thu Jul  9 21:45:21 2020
--------------
Traceback (most recent call last):

--------------

	Thu Jul  9 21:45:21 2020
--------------

--------------

	Thu Jul  9 21:45:21 2020
--------------
  File "D:\Program Files\JetBrains\PyCharm Community Edition 2018.3.4\plugins\python-ce\helpers\pydev\_pydevd_bundle\pydevd_comm.py", line 294, in _on_run
    r = r.decode('utf-8')

--------------

	Thu Jul  9 21:45:21 2020
--------------

--------------

	Thu Jul  9 21:45:21 2020
--------------
UnicodeDecodeError: 'utf-8' codec can't decode byte 0xe8 in position 1023: unexpected end of data

--------------

	Thu Jul  9 21:45:21 2020
--------------

--------------

	Thu Jul  9 21:46:39 2020
--------------
Traceback (most recent call last):

--------------

	Thu Jul  9 21:46:39 2020
--------------

--------------

	Thu Jul  9 21:46:39 2020
--------------
  File "D:\Program Files\JetBrains\PyCharm Community Edition 2018.3.4\plugins\python-ce\helpers\pydev\_pydevd_bundle\pydevd_comm.py", line 294, in _on_run
    r = r.decode('utf-8')

--------------

	Thu Jul  9 21:46:39 2020
--------------

--------------

	Thu Jul  9 21:46:39 2020
--------------
UnicodeDecodeError: 'utf-8' codec can't decode bytes in position 1022-1023: unexpected end of data

--------------

	Thu Jul  9 21:46:39 2020
--------------

--------------

	Sun Jul 12 09:24:06 2020
--------------
Traceback (most recent call last):

--------------

	Sun Jul 12 09:24:06 2020
--------------
  File "D:\project\碧蓝航线立绘导出2.0\core\src\frame_classes\main_frame.py", line 481, in work

--------------

	Sun Jul 12 09:24:06 2020
--------------
    self.export_all(temp, self.painting_work)

--------------

	Sun Jul 12 09:24:06 2020
--------------
  File "D:\project\碧蓝航线立绘导出2.0\core\src\frame_classes\main_frame.py", line 302, in export_all

--------------

	Sun Jul 12 09:24:06 2020
--------------
    self.restart(len(able), able, for_work.build_unable())

--------------

	Sun Jul 12 09:24:06 2020
--------------
  File "D:\project\碧蓝航线立绘导出2.0\core\src\frame_classes\main_frame.py", line 230, in restart

--------------

	Sun Jul 12 09:24:06 2020
--------------
    self.thread_watch_dog = WatchDogThread(self.work_queue, self.err_queue, able, self.locker)

--------------

	Sun Jul 12 09:24:06 2020
--------------
TypeError: __init__() missing 4 required positional arguments: 'frame', 'setting', 'size', and 'threads'

--------------

	Sun Jul 12 09:25:51 2020
--------------
Traceback (most recent call last):

--------------

	Sun Jul 12 09:25:51 2020
--------------
  File "C:\Users\qz228\AppData\Local\Programs\Python\Python37\lib\threading.py", line 926, in _bootstrap_inner

--------------

	Sun Jul 12 09:25:51 2020
--------------
Traceback (most recent call last):

--------------

	Sun Jul 12 09:25:51 2020
--------------
      File "D:\project\碧蓝航线立绘导出2.0\core\src\frame_classes\main_frame.py", line 483, in work

--------------

	Sun Jul 12 09:25:51 2020
--------------
self.run()    

--------------

	Sun Jul 12 09:25:51 2020
--------------
self.export_all(temp, self.painting_work)  File "D:\project\碧蓝航线立绘导出2.0\core\src\thread_classes\extract_thread.py", line 375, in run

--------------

	Sun Jul 12 09:25:51 2020
--------------


--------------

	Sun Jul 12 09:25:51 2020
--------------
      File "D:\project\碧蓝航线立绘导出2.0\core\src\frame_classes\main_frame.py", line 308, in export_all

--------------

	Sun Jul 12 09:25:51 2020
--------------
if reduce(lambda x, y: x.is_alive() and y.is_alive(), self.threads, True):

--------------

	Sun Jul 12 09:25:51 2020
--------------
      File "D:\project\碧蓝航线立绘导出2.0\core\src\thread_classes\extract_thread.py", line 375, in <lambda>

--------------

	Sun Jul 12 09:25:51 2020
--------------
thread.start()

--------------

	Sun Jul 12 09:25:51 2020
--------------
      File "C:\Users\qz228\AppData\Local\Programs\Python\Python37\lib\threading.py", line 848, in start

--------------

	Sun Jul 12 09:25:51 2020
--------------
if reduce(lambda x, y: x.is_alive() and y.is_alive(), self.threads, True):    

--------------
AttributeError09:25:51 2020
--------------
raise RuntimeError("threads can only be started once")

--------------

	Sun Jul 12 09:25:51 2020
--------------
: 'bool' object has no attribute 'is_alive'RuntimeError

--------------

	Sun Jul 12 09:25:51 2020
--------------
: threads can only be started once

--------------

	Sun Jul 12 09:25:51 2020
--------------
Exception in thread watch dog:
Traceback (most recent call last):
  File "C:\Users\qz228\AppData\Local\Programs\Python\Python37\lib\threading.py", line 926, in _bootstrap_inner
    self.run()
  File "D:\project\碧蓝航线立绘导出2.0\core\src\thread_classes\extract_thread.py", line 375, in run
    if reduce(lambda x, y: x.is_alive() and y.is_alive(), self.threads, True):
  File "D:\project\碧蓝航线立绘导出2.0\core\src\thread_classes\extract_thread.py", line 375, in <lambda>
    if reduce(lambda x, y: x.is_alive() and y.is_alive(), self.threads, True):
AttributeError: 'bool' object has no attribute 'is_alive'

--------------

	Sun Jul 12 09:25:51 2020
--------------


--------------

	Sun Jul 12 09:26:33 2020
--------------
Traceback (most recent call last):

--------------

	Sun Jul 12 09:26:33 2020
--------------
  File "D:\project\碧蓝航线立绘导出2.0\core\src\frame_classes\main_frame.py", line 483, in work

--------------

	Sun Jul 12 09:26:33 2020
--------------
    self.export_all(temp, self.painting_work)

--------------

	Sun Jul 12 09:26:33 2020
--------------
  File "D:\project\碧蓝航线立绘导出2.0\core\src\frame_classes\main_frame.py", line 308, in export_all

--------------

	Sun Jul 12 09:26:33 2020
--------------
    thread.start()

--------------

	Sun Jul 12 09:26:33 2020
--------------
  File "C:\Users\qz228\AppData\Local\Programs\Python\Python37\lib\threading.py", line 848, in start

--------------

	Sun Jul 12 09:26:33 2020
--------------
    raise RuntimeError("threads can only be started once")

--------------

	Sun Jul 12 09:26:33 2020
--------------
RuntimeError: threads can only be started once

--------------

	Sun Jul 12 09:33:33 2020
--------------
Traceback (most recent call last):

--------------

	Sun Jul 12 09:33:33 2020
--------------
  File "D:\project\碧蓝航线立绘导出2.0\core\src\frame_classes\main_frame.py", line 483, in work

--------------

	Sun Jul 12 09:33:33 2020
--------------
    self.export_all(temp, self.painting_work)

--------------

	Sun Jul 12 09:33:33 2020
--------------
  File "D:\project\碧蓝航线立绘导出2.0\core\src\frame_classes\main_frame.py", line 308, in export_all

--------------

	Sun Jul 12 09:33:33 2020
--------------
    thread.start()

--------------

	Sun Jul 12 09:33:33 2020
--------------
  File "C:\Users\qz228\AppData\Local\Programs\Python\Python37\lib\threading.py", line 848, in start

--------------

	Sun Jul 12 09:33:33 2020
--------------
    raise RuntimeError("threads can only be started once")

--------------

	Sun Jul 12 09:33:33 2020
--------------
RuntimeError: threads can only be started once

--------------

	Sun Jul 12 09:47:35 2020
--------------
Exception in thread thread-1:
Traceback (most recent call last):
  File "D:\project\碧蓝航线立绘导出2.0\core\src\thread_classes\extract_thread.py", line 273, in run
    self.format.m_gauge_state.SetValue(val)
RuntimeError: wrapped C/C++ object of type Gauge has been deleted

During handling of the above exception, another exception occurred:

Traceback (most recent call last):
  File "C:\Users\qz228\AppData\Local\Programs\Python\Python37\lib\threading.py", line 926, in _bootstrap_inner
    self.run()
  File "D:\project\碧蓝航线立绘导出2.0\core\src\thread_classes\extract_thread.py", line 277, in run
    self.format.m_staticText_info.SetLabel(f"处理出错！，为{info},在{self.name}")
RuntimeError: wrapped C/C++ object of type StaticText has been deleted

--------------

	Sun Jul 12 09:47:35 2020
--------------


--------------

	Sun Jul 12 09:49:07 2020
--------------
Exception in thread thread-1:
Traceback (most recent call last):
  File "D:\project\碧蓝航线立绘导出2.0\core\src\thread_classes\extract_thread.py", line 273, in run
    self.format.m_gauge_state.SetValue(val)
RuntimeError: wrapped C/C++ object of type Gauge has been deleted

During handling of the above exception, another exception occurred:

Traceback (most recent call last):
  File "C:\Users\qz228\AppData\Local\Programs\Python\Python37\lib\threading.py", line 926, in _bootstrap_inner
    self.run()
  File "D:\project\碧蓝航线立绘导出2.0\core\src\thread_classes\extract_thread.py", line 277, in run
    self.format.m_staticText_info.SetLabel(f"处理出错！，为{info},在{self.name}")
RuntimeError: wrapped C/C++ object of type StaticText has been deleted

--------------

	Sun Jul 12 09:49:07 2020
--------------


--------------
